<?xml version="1.0" encoding="UTF-8"?>
<!-- Generated by org.testng.reporters.JUnitXMLReporter -->
<testsuite ignored="0" hostname="Keekee" failures="1" tests="2" name="Parallel Order Count Verification" time="28.165" errors="0" timestamp="2025-08-07T23:43:12 IST">
  <testcase classname="testCases.TC014_OutOfStockAlertinCart" name="test_VerifyOutOfStockAlert" time="19.423">
    <failure type="java.lang.AssertionError" message="Test failed due to an exception.">
      <![CDATA[java.lang.AssertionError: Test failed due to an exception.
at testCases.TC014_OutOfStockAlertinCart.test_VerifyOutOfStockAlert(TC014_OutOfStockAlertinCart.java:38)
at java.base/java.util.concurrent.Executors$RunnableAdapter.call(Executors.java:572)
at java.base/java.util.concurrent.FutureTask.run(FutureTask.java:317)
at java.base/java.util.concurrent.ThreadPoolExecutor.runWorker(ThreadPoolExecutor.java:1144)
at java.base/java.util.concurrent.ThreadPoolExecutor$Worker.run(ThreadPoolExecutor.java:642)
at java.base/java.lang.Thread.run(Thread.java:1583)
... Removed 12 stack frames]]>
    </failure>
  </testcase> <!-- test_VerifyOutOfStockAlert -->
  <testcase classname="testCases.TC013_OutOfStockProdToCart" name="test_VerifyOutOfStockProdToCart" time="19.828"/>
</testsuite> <!-- Parallel Order Count Verification -->
